[2023-04-11T10:25:18.901+0000] {processor.py:153} INFO - Started process (PID=1904) to work on /opt/airflow/dags/dag_triggers_another_dag.py
[2023-04-11T10:25:18.904+0000] {processor.py:743} INFO - Processing file /opt/airflow/dags/dag_triggers_another_dag.py for tasks to queue
[2023-04-11T10:25:18.907+0000] {logging_mixin.py:137} INFO - [2023-04-11T10:25:18.907+0000] {dagbag.py:532} INFO - Filling up the DagBag from /opt/airflow/dags/dag_triggers_another_dag.py
[2023-04-11T10:25:19.038+0000] {processor.py:753} INFO - DAG(s) dict_keys(['dag1']) retrieved from /opt/airflow/dags/dag_triggers_another_dag.py
[2023-04-11T10:25:20.290+0000] {logging_mixin.py:137} INFO - [2023-04-11T10:25:20.289+0000] {manager.py:504} INFO - Created Permission View: can edit on DAG:dag1
[2023-04-11T10:25:20.375+0000] {logging_mixin.py:137} INFO - [2023-04-11T10:25:20.374+0000] {manager.py:504} INFO - Created Permission View: can delete on DAG:dag1
[2023-04-11T10:25:20.406+0000] {logging_mixin.py:137} INFO - [2023-04-11T10:25:20.402+0000] {manager.py:504} INFO - Created Permission View: can read on DAG:dag1
[2023-04-11T10:25:20.409+0000] {logging_mixin.py:137} INFO - [2023-04-11T10:25:20.408+0000] {dag.py:2705} INFO - Sync 1 DAGs
[2023-04-11T10:25:20.482+0000] {logging_mixin.py:137} INFO - [2023-04-11T10:25:20.482+0000] {dag.py:2726} INFO - Creating ORM DAG for dag1
[2023-04-11T10:25:20.560+0000] {logging_mixin.py:137} INFO - [2023-04-11T10:25:20.552+0000] {dag.py:3456} INFO - Setting next_dagrun for dag1 to None, run_after=None
[2023-04-11T10:25:20.721+0000] {processor.py:175} INFO - Processing /opt/airflow/dags/dag_triggers_another_dag.py took 1.831 seconds
[2023-04-11T10:25:51.448+0000] {processor.py:153} INFO - Started process (PID=1941) to work on /opt/airflow/dags/dag_triggers_another_dag.py
[2023-04-11T10:25:51.460+0000] {processor.py:743} INFO - Processing file /opt/airflow/dags/dag_triggers_another_dag.py for tasks to queue
[2023-04-11T10:25:51.462+0000] {logging_mixin.py:137} INFO - [2023-04-11T10:25:51.462+0000] {dagbag.py:532} INFO - Filling up the DagBag from /opt/airflow/dags/dag_triggers_another_dag.py
[2023-04-11T10:25:51.617+0000] {processor.py:753} INFO - DAG(s) dict_keys(['dag1']) retrieved from /opt/airflow/dags/dag_triggers_another_dag.py
[2023-04-11T10:25:51.740+0000] {logging_mixin.py:137} INFO - [2023-04-11T10:25:51.740+0000] {dag.py:2705} INFO - Sync 1 DAGs
[2023-04-11T10:25:51.922+0000] {logging_mixin.py:137} INFO - [2023-04-11T10:25:51.922+0000] {dag.py:3456} INFO - Setting next_dagrun for dag1 to None, run_after=None
[2023-04-11T10:25:52.020+0000] {processor.py:175} INFO - Processing /opt/airflow/dags/dag_triggers_another_dag.py took 0.592 seconds
[2023-04-11T10:26:22.257+0000] {processor.py:153} INFO - Started process (PID=1978) to work on /opt/airflow/dags/dag_triggers_another_dag.py
[2023-04-11T10:26:22.258+0000] {processor.py:743} INFO - Processing file /opt/airflow/dags/dag_triggers_another_dag.py for tasks to queue
[2023-04-11T10:26:22.260+0000] {logging_mixin.py:137} INFO - [2023-04-11T10:26:22.260+0000] {dagbag.py:532} INFO - Filling up the DagBag from /opt/airflow/dags/dag_triggers_another_dag.py
[2023-04-11T10:26:22.313+0000] {processor.py:753} INFO - DAG(s) dict_keys(['dag1']) retrieved from /opt/airflow/dags/dag_triggers_another_dag.py
[2023-04-11T10:26:22.355+0000] {logging_mixin.py:137} INFO - [2023-04-11T10:26:22.355+0000] {dag.py:2705} INFO - Sync 1 DAGs
[2023-04-11T10:26:22.410+0000] {logging_mixin.py:137} INFO - [2023-04-11T10:26:22.410+0000] {dag.py:3456} INFO - Setting next_dagrun for dag1 to None, run_after=None
[2023-04-11T10:26:22.454+0000] {processor.py:175} INFO - Processing /opt/airflow/dags/dag_triggers_another_dag.py took 0.207 seconds
[2023-04-11T10:26:52.731+0000] {processor.py:153} INFO - Started process (PID=2015) to work on /opt/airflow/dags/dag_triggers_another_dag.py
[2023-04-11T10:26:52.746+0000] {processor.py:743} INFO - Processing file /opt/airflow/dags/dag_triggers_another_dag.py for tasks to queue
[2023-04-11T10:26:52.749+0000] {logging_mixin.py:137} INFO - [2023-04-11T10:26:52.749+0000] {dagbag.py:532} INFO - Filling up the DagBag from /opt/airflow/dags/dag_triggers_another_dag.py
[2023-04-11T10:26:52.883+0000] {processor.py:753} INFO - DAG(s) dict_keys(['dag1']) retrieved from /opt/airflow/dags/dag_triggers_another_dag.py
[2023-04-11T10:26:52.950+0000] {logging_mixin.py:137} INFO - [2023-04-11T10:26:52.950+0000] {dag.py:2705} INFO - Sync 1 DAGs
[2023-04-11T10:26:53.073+0000] {logging_mixin.py:137} INFO - [2023-04-11T10:26:53.073+0000] {dag.py:3456} INFO - Setting next_dagrun for dag1 to None, run_after=None
[2023-04-11T10:26:53.160+0000] {processor.py:175} INFO - Processing /opt/airflow/dags/dag_triggers_another_dag.py took 0.439 seconds
[2023-04-11T10:27:18.588+0000] {processor.py:153} INFO - Started process (PID=2052) to work on /opt/airflow/dags/dag_triggers_another_dag.py
[2023-04-11T10:27:18.590+0000] {processor.py:743} INFO - Processing file /opt/airflow/dags/dag_triggers_another_dag.py for tasks to queue
[2023-04-11T10:27:18.602+0000] {logging_mixin.py:137} INFO - [2023-04-11T10:27:18.601+0000] {dagbag.py:532} INFO - Filling up the DagBag from /opt/airflow/dags/dag_triggers_another_dag.py
[2023-04-11T10:27:19.065+0000] {logging_mixin.py:137} INFO - [2023-04-11T10:27:18.926+0000] {dagbag.py:341} ERROR - Failed to import: /opt/airflow/dags/dag_triggers_another_dag.py
Traceback (most recent call last):
  File "/home/airflow/.local/lib/python3.7/site-packages/airflow/models/dagbag.py", line 337, in parse
    loader.exec_module(new_module)
  File "<frozen importlib._bootstrap_external>", line 728, in exec_module
  File "<frozen importlib._bootstrap>", line 219, in _call_with_frames_removed
  File "/opt/airflow/dags/dag_triggers_another_dag.py", line 58, in <module>
    dag1 >> dag2
TypeError: unsupported operand type(s) for >>: 'DAG' and 'DAG'
[2023-04-11T10:27:19.080+0000] {processor.py:755} WARNING - No viable dags retrieved from /opt/airflow/dags/dag_triggers_another_dag.py
[2023-04-11T10:27:19.164+0000] {processor.py:175} INFO - Processing /opt/airflow/dags/dag_triggers_another_dag.py took 0.585 seconds
[2023-04-11T10:27:49.529+0000] {processor.py:153} INFO - Started process (PID=2088) to work on /opt/airflow/dags/dag_triggers_another_dag.py
[2023-04-11T10:27:49.531+0000] {processor.py:743} INFO - Processing file /opt/airflow/dags/dag_triggers_another_dag.py for tasks to queue
[2023-04-11T10:27:49.532+0000] {logging_mixin.py:137} INFO - [2023-04-11T10:27:49.532+0000] {dagbag.py:532} INFO - Filling up the DagBag from /opt/airflow/dags/dag_triggers_another_dag.py
[2023-04-11T10:27:49.585+0000] {logging_mixin.py:137} INFO - [2023-04-11T10:27:49.578+0000] {dagbag.py:341} ERROR - Failed to import: /opt/airflow/dags/dag_triggers_another_dag.py
Traceback (most recent call last):
  File "/home/airflow/.local/lib/python3.7/site-packages/airflow/models/dagbag.py", line 337, in parse
    loader.exec_module(new_module)
  File "<frozen importlib._bootstrap_external>", line 728, in exec_module
  File "<frozen importlib._bootstrap>", line 219, in _call_with_frames_removed
  File "/opt/airflow/dags/dag_triggers_another_dag.py", line 58, in <module>
    dag1 >> dag2
TypeError: unsupported operand type(s) for >>: 'DAG' and 'DAG'
[2023-04-11T10:27:49.588+0000] {processor.py:755} WARNING - No viable dags retrieved from /opt/airflow/dags/dag_triggers_another_dag.py
[2023-04-11T10:27:49.635+0000] {processor.py:175} INFO - Processing /opt/airflow/dags/dag_triggers_another_dag.py took 0.111 seconds
[2023-04-11T10:28:19.915+0000] {processor.py:153} INFO - Started process (PID=2125) to work on /opt/airflow/dags/dag_triggers_another_dag.py
[2023-04-11T10:28:19.922+0000] {processor.py:743} INFO - Processing file /opt/airflow/dags/dag_triggers_another_dag.py for tasks to queue
[2023-04-11T10:28:19.926+0000] {logging_mixin.py:137} INFO - [2023-04-11T10:28:19.926+0000] {dagbag.py:532} INFO - Filling up the DagBag from /opt/airflow/dags/dag_triggers_another_dag.py
[2023-04-11T10:28:20.034+0000] {logging_mixin.py:137} INFO - [2023-04-11T10:28:20.025+0000] {dagbag.py:341} ERROR - Failed to import: /opt/airflow/dags/dag_triggers_another_dag.py
Traceback (most recent call last):
  File "/home/airflow/.local/lib/python3.7/site-packages/airflow/models/dagbag.py", line 337, in parse
    loader.exec_module(new_module)
  File "<frozen importlib._bootstrap_external>", line 728, in exec_module
  File "<frozen importlib._bootstrap>", line 219, in _call_with_frames_removed
  File "/opt/airflow/dags/dag_triggers_another_dag.py", line 58, in <module>
    dag1 >> dag2
TypeError: unsupported operand type(s) for >>: 'DAG' and 'DAG'
[2023-04-11T10:28:20.038+0000] {processor.py:755} WARNING - No viable dags retrieved from /opt/airflow/dags/dag_triggers_another_dag.py
[2023-04-11T10:28:20.105+0000] {processor.py:175} INFO - Processing /opt/airflow/dags/dag_triggers_another_dag.py took 0.210 seconds
[2023-04-11T10:28:50.496+0000] {processor.py:153} INFO - Started process (PID=2162) to work on /opt/airflow/dags/dag_triggers_another_dag.py
[2023-04-11T10:28:50.498+0000] {processor.py:743} INFO - Processing file /opt/airflow/dags/dag_triggers_another_dag.py for tasks to queue
[2023-04-11T10:28:50.500+0000] {logging_mixin.py:137} INFO - [2023-04-11T10:28:50.500+0000] {dagbag.py:532} INFO - Filling up the DagBag from /opt/airflow/dags/dag_triggers_another_dag.py
[2023-04-11T10:28:50.548+0000] {logging_mixin.py:137} INFO - [2023-04-11T10:28:50.540+0000] {dagbag.py:341} ERROR - Failed to import: /opt/airflow/dags/dag_triggers_another_dag.py
Traceback (most recent call last):
  File "/home/airflow/.local/lib/python3.7/site-packages/airflow/models/dagbag.py", line 337, in parse
    loader.exec_module(new_module)
  File "<frozen importlib._bootstrap_external>", line 728, in exec_module
  File "<frozen importlib._bootstrap>", line 219, in _call_with_frames_removed
  File "/opt/airflow/dags/dag_triggers_another_dag.py", line 58, in <module>
    dag1 >> dag2
TypeError: unsupported operand type(s) for >>: 'DAG' and 'DAG'
[2023-04-11T10:28:50.551+0000] {processor.py:755} WARNING - No viable dags retrieved from /opt/airflow/dags/dag_triggers_another_dag.py
[2023-04-11T10:28:50.583+0000] {processor.py:175} INFO - Processing /opt/airflow/dags/dag_triggers_another_dag.py took 0.092 seconds
[2023-04-11T10:29:15.680+0000] {processor.py:153} INFO - Started process (PID=2199) to work on /opt/airflow/dags/dag_triggers_another_dag.py
[2023-04-11T10:29:15.692+0000] {processor.py:743} INFO - Processing file /opt/airflow/dags/dag_triggers_another_dag.py for tasks to queue
[2023-04-11T10:29:15.695+0000] {logging_mixin.py:137} INFO - [2023-04-11T10:29:15.694+0000] {dagbag.py:532} INFO - Filling up the DagBag from /opt/airflow/dags/dag_triggers_another_dag.py
[2023-04-11T10:29:15.872+0000] {logging_mixin.py:137} INFO - [2023-04-11T10:29:15.862+0000] {dagbag.py:341} ERROR - Failed to import: /opt/airflow/dags/dag_triggers_another_dag.py
Traceback (most recent call last):
  File "/home/airflow/.local/lib/python3.7/site-packages/airflow/models/dagbag.py", line 337, in parse
    loader.exec_module(new_module)
  File "<frozen importlib._bootstrap_external>", line 728, in exec_module
  File "<frozen importlib._bootstrap>", line 219, in _call_with_frames_removed
  File "/opt/airflow/dags/dag_triggers_another_dag.py", line 58, in <module>
    dag1 >> dag2
TypeError: unsupported operand type(s) for >>: 'DAG' and 'DAG'
[2023-04-11T10:29:15.875+0000] {processor.py:755} WARNING - No viable dags retrieved from /opt/airflow/dags/dag_triggers_another_dag.py
[2023-04-11T10:29:15.951+0000] {processor.py:175} INFO - Processing /opt/airflow/dags/dag_triggers_another_dag.py took 0.286 seconds
[2023-04-11T10:29:46.535+0000] {processor.py:153} INFO - Started process (PID=2237) to work on /opt/airflow/dags/dag_triggers_another_dag.py
[2023-04-11T10:29:46.543+0000] {processor.py:743} INFO - Processing file /opt/airflow/dags/dag_triggers_another_dag.py for tasks to queue
[2023-04-11T10:29:46.546+0000] {logging_mixin.py:137} INFO - [2023-04-11T10:29:46.546+0000] {dagbag.py:532} INFO - Filling up the DagBag from /opt/airflow/dags/dag_triggers_another_dag.py
[2023-04-11T10:29:46.721+0000] {logging_mixin.py:137} INFO - [2023-04-11T10:29:46.618+0000] {dagbag.py:341} ERROR - Failed to import: /opt/airflow/dags/dag_triggers_another_dag.py
Traceback (most recent call last):
  File "/home/airflow/.local/lib/python3.7/site-packages/airflow/models/dagbag.py", line 337, in parse
    loader.exec_module(new_module)
  File "<frozen importlib._bootstrap_external>", line 728, in exec_module
  File "<frozen importlib._bootstrap>", line 219, in _call_with_frames_removed
  File "/opt/airflow/dags/dag_triggers_another_dag.py", line 58, in <module>
    dag1 >> dag2
TypeError: unsupported operand type(s) for >>: 'DAG' and 'DAG'
[2023-04-11T10:29:46.725+0000] {processor.py:755} WARNING - No viable dags retrieved from /opt/airflow/dags/dag_triggers_another_dag.py
[2023-04-11T10:29:46.791+0000] {processor.py:175} INFO - Processing /opt/airflow/dags/dag_triggers_another_dag.py took 0.267 seconds
[2023-04-11T10:30:17.559+0000] {processor.py:153} INFO - Started process (PID=2278) to work on /opt/airflow/dags/dag_triggers_another_dag.py
[2023-04-11T10:30:17.561+0000] {processor.py:743} INFO - Processing file /opt/airflow/dags/dag_triggers_another_dag.py for tasks to queue
[2023-04-11T10:30:17.563+0000] {logging_mixin.py:137} INFO - [2023-04-11T10:30:17.563+0000] {dagbag.py:532} INFO - Filling up the DagBag from /opt/airflow/dags/dag_triggers_another_dag.py
[2023-04-11T10:30:17.635+0000] {logging_mixin.py:137} INFO - [2023-04-11T10:30:17.624+0000] {dagbag.py:341} ERROR - Failed to import: /opt/airflow/dags/dag_triggers_another_dag.py
Traceback (most recent call last):
  File "/home/airflow/.local/lib/python3.7/site-packages/airflow/models/dagbag.py", line 337, in parse
    loader.exec_module(new_module)
  File "<frozen importlib._bootstrap_external>", line 728, in exec_module
  File "<frozen importlib._bootstrap>", line 219, in _call_with_frames_removed
  File "/opt/airflow/dags/dag_triggers_another_dag.py", line 58, in <module>
    dag1 >> dag2
TypeError: unsupported operand type(s) for >>: 'DAG' and 'DAG'
[2023-04-11T10:30:17.639+0000] {processor.py:755} WARNING - No viable dags retrieved from /opt/airflow/dags/dag_triggers_another_dag.py
[2023-04-11T10:30:17.698+0000] {processor.py:175} INFO - Processing /opt/airflow/dags/dag_triggers_another_dag.py took 0.147 seconds
[2023-04-11T10:30:47.900+0000] {processor.py:153} INFO - Started process (PID=2316) to work on /opt/airflow/dags/dag_triggers_another_dag.py
[2023-04-11T10:30:47.904+0000] {processor.py:743} INFO - Processing file /opt/airflow/dags/dag_triggers_another_dag.py for tasks to queue
[2023-04-11T10:30:47.907+0000] {logging_mixin.py:137} INFO - [2023-04-11T10:30:47.907+0000] {dagbag.py:532} INFO - Filling up the DagBag from /opt/airflow/dags/dag_triggers_another_dag.py
[2023-04-11T10:30:48.013+0000] {logging_mixin.py:137} INFO - [2023-04-11T10:30:48.004+0000] {dagbag.py:341} ERROR - Failed to import: /opt/airflow/dags/dag_triggers_another_dag.py
Traceback (most recent call last):
  File "/home/airflow/.local/lib/python3.7/site-packages/airflow/models/dagbag.py", line 337, in parse
    loader.exec_module(new_module)
  File "<frozen importlib._bootstrap_external>", line 728, in exec_module
  File "<frozen importlib._bootstrap>", line 219, in _call_with_frames_removed
  File "/opt/airflow/dags/dag_triggers_another_dag.py", line 70, in <module>
    trigger >> task3 >> task4
  File "/home/airflow/.local/lib/python3.7/site-packages/airflow/models/taskmixin.py", line 87, in __rshift__
    self.set_downstream(other)
  File "/home/airflow/.local/lib/python3.7/site-packages/airflow/models/taskmixin.py", line 236, in set_downstream
    self._set_relatives(task_or_task_list, upstream=False, edge_modifier=edge_modifier)
  File "/home/airflow/.local/lib/python3.7/site-packages/airflow/models/taskmixin.py", line 195, in _set_relatives
    raise AirflowException(f"Tried to set relationships between tasks in more than one DAG: {dags}")
airflow.exceptions.AirflowException: Tried to set relationships between tasks in more than one DAG: {<DAG: dag1>, <DAG: dag2>}
[2023-04-11T10:30:48.014+0000] {processor.py:755} WARNING - No viable dags retrieved from /opt/airflow/dags/dag_triggers_another_dag.py
[2023-04-11T10:30:48.049+0000] {processor.py:175} INFO - Processing /opt/airflow/dags/dag_triggers_another_dag.py took 0.164 seconds
[2023-04-11T10:31:19.006+0000] {processor.py:153} INFO - Started process (PID=2353) to work on /opt/airflow/dags/dag_triggers_another_dag.py
[2023-04-11T10:31:19.008+0000] {processor.py:743} INFO - Processing file /opt/airflow/dags/dag_triggers_another_dag.py for tasks to queue
[2023-04-11T10:31:19.010+0000] {logging_mixin.py:137} INFO - [2023-04-11T10:31:19.010+0000] {dagbag.py:532} INFO - Filling up the DagBag from /opt/airflow/dags/dag_triggers_another_dag.py
[2023-04-11T10:31:19.095+0000] {logging_mixin.py:137} INFO - [2023-04-11T10:31:19.084+0000] {dagbag.py:341} ERROR - Failed to import: /opt/airflow/dags/dag_triggers_another_dag.py
Traceback (most recent call last):
  File "/home/airflow/.local/lib/python3.7/site-packages/airflow/models/dagbag.py", line 337, in parse
    loader.exec_module(new_module)
  File "<frozen importlib._bootstrap_external>", line 728, in exec_module
  File "<frozen importlib._bootstrap>", line 219, in _call_with_frames_removed
  File "/opt/airflow/dags/dag_triggers_another_dag.py", line 70, in <module>
    trigger >> task3 >> task4
  File "/home/airflow/.local/lib/python3.7/site-packages/airflow/models/taskmixin.py", line 87, in __rshift__
    self.set_downstream(other)
  File "/home/airflow/.local/lib/python3.7/site-packages/airflow/models/taskmixin.py", line 236, in set_downstream
    self._set_relatives(task_or_task_list, upstream=False, edge_modifier=edge_modifier)
  File "/home/airflow/.local/lib/python3.7/site-packages/airflow/models/taskmixin.py", line 195, in _set_relatives
    raise AirflowException(f"Tried to set relationships between tasks in more than one DAG: {dags}")
airflow.exceptions.AirflowException: Tried to set relationships between tasks in more than one DAG: {<DAG: dag1>, <DAG: dag2>}
[2023-04-11T10:31:19.096+0000] {processor.py:755} WARNING - No viable dags retrieved from /opt/airflow/dags/dag_triggers_another_dag.py
[2023-04-11T10:31:19.150+0000] {processor.py:175} INFO - Processing /opt/airflow/dags/dag_triggers_another_dag.py took 0.149 seconds
[2023-04-11T10:31:49.515+0000] {processor.py:153} INFO - Started process (PID=2390) to work on /opt/airflow/dags/dag_triggers_another_dag.py
[2023-04-11T10:31:49.518+0000] {processor.py:743} INFO - Processing file /opt/airflow/dags/dag_triggers_another_dag.py for tasks to queue
[2023-04-11T10:31:49.521+0000] {logging_mixin.py:137} INFO - [2023-04-11T10:31:49.520+0000] {dagbag.py:532} INFO - Filling up the DagBag from /opt/airflow/dags/dag_triggers_another_dag.py
[2023-04-11T10:31:49.597+0000] {logging_mixin.py:137} INFO - [2023-04-11T10:31:49.587+0000] {dagbag.py:341} ERROR - Failed to import: /opt/airflow/dags/dag_triggers_another_dag.py
Traceback (most recent call last):
  File "/home/airflow/.local/lib/python3.7/site-packages/airflow/models/dagbag.py", line 337, in parse
    loader.exec_module(new_module)
  File "<frozen importlib._bootstrap_external>", line 728, in exec_module
  File "<frozen importlib._bootstrap>", line 219, in _call_with_frames_removed
  File "/opt/airflow/dags/dag_triggers_another_dag.py", line 70, in <module>
    trigger >> task3 >> task4
  File "/home/airflow/.local/lib/python3.7/site-packages/airflow/models/taskmixin.py", line 87, in __rshift__
    self.set_downstream(other)
  File "/home/airflow/.local/lib/python3.7/site-packages/airflow/models/taskmixin.py", line 236, in set_downstream
    self._set_relatives(task_or_task_list, upstream=False, edge_modifier=edge_modifier)
  File "/home/airflow/.local/lib/python3.7/site-packages/airflow/models/taskmixin.py", line 195, in _set_relatives
    raise AirflowException(f"Tried to set relationships between tasks in more than one DAG: {dags}")
airflow.exceptions.AirflowException: Tried to set relationships between tasks in more than one DAG: {<DAG: dag2>, <DAG: dag1>}
[2023-04-11T10:31:49.598+0000] {processor.py:755} WARNING - No viable dags retrieved from /opt/airflow/dags/dag_triggers_another_dag.py
[2023-04-11T10:31:49.651+0000] {processor.py:175} INFO - Processing /opt/airflow/dags/dag_triggers_another_dag.py took 0.142 seconds
[2023-04-11T10:32:20.370+0000] {processor.py:153} INFO - Started process (PID=2427) to work on /opt/airflow/dags/dag_triggers_another_dag.py
[2023-04-11T10:32:20.382+0000] {processor.py:743} INFO - Processing file /opt/airflow/dags/dag_triggers_another_dag.py for tasks to queue
[2023-04-11T10:32:20.384+0000] {logging_mixin.py:137} INFO - [2023-04-11T10:32:20.384+0000] {dagbag.py:532} INFO - Filling up the DagBag from /opt/airflow/dags/dag_triggers_another_dag.py
[2023-04-11T10:32:20.516+0000] {logging_mixin.py:137} INFO - [2023-04-11T10:32:20.475+0000] {dagbag.py:341} ERROR - Failed to import: /opt/airflow/dags/dag_triggers_another_dag.py
Traceback (most recent call last):
  File "/home/airflow/.local/lib/python3.7/site-packages/airflow/models/dagbag.py", line 337, in parse
    loader.exec_module(new_module)
  File "<frozen importlib._bootstrap_external>", line 728, in exec_module
  File "<frozen importlib._bootstrap>", line 219, in _call_with_frames_removed
  File "/opt/airflow/dags/dag_triggers_another_dag.py", line 70, in <module>
    trigger >> task3 >> task4
  File "/home/airflow/.local/lib/python3.7/site-packages/airflow/models/taskmixin.py", line 87, in __rshift__
    self.set_downstream(other)
  File "/home/airflow/.local/lib/python3.7/site-packages/airflow/models/taskmixin.py", line 236, in set_downstream
    self._set_relatives(task_or_task_list, upstream=False, edge_modifier=edge_modifier)
  File "/home/airflow/.local/lib/python3.7/site-packages/airflow/models/taskmixin.py", line 195, in _set_relatives
    raise AirflowException(f"Tried to set relationships between tasks in more than one DAG: {dags}")
airflow.exceptions.AirflowException: Tried to set relationships between tasks in more than one DAG: {<DAG: dag1>, <DAG: dag2>}
[2023-04-11T10:32:20.519+0000] {processor.py:755} WARNING - No viable dags retrieved from /opt/airflow/dags/dag_triggers_another_dag.py
[2023-04-11T10:32:20.577+0000] {processor.py:175} INFO - Processing /opt/airflow/dags/dag_triggers_another_dag.py took 0.221 seconds
[2023-04-11T10:32:51.065+0000] {processor.py:153} INFO - Started process (PID=2464) to work on /opt/airflow/dags/dag_triggers_another_dag.py
[2023-04-11T10:32:51.072+0000] {processor.py:743} INFO - Processing file /opt/airflow/dags/dag_triggers_another_dag.py for tasks to queue
[2023-04-11T10:32:51.079+0000] {logging_mixin.py:137} INFO - [2023-04-11T10:32:51.078+0000] {dagbag.py:532} INFO - Filling up the DagBag from /opt/airflow/dags/dag_triggers_another_dag.py
[2023-04-11T10:32:51.205+0000] {logging_mixin.py:137} INFO - [2023-04-11T10:32:51.193+0000] {dagbag.py:341} ERROR - Failed to import: /opt/airflow/dags/dag_triggers_another_dag.py
Traceback (most recent call last):
  File "/home/airflow/.local/lib/python3.7/site-packages/airflow/models/dagbag.py", line 337, in parse
    loader.exec_module(new_module)
  File "<frozen importlib._bootstrap_external>", line 728, in exec_module
  File "<frozen importlib._bootstrap>", line 219, in _call_with_frames_removed
  File "/opt/airflow/dags/dag_triggers_another_dag.py", line 70, in <module>
    trigger >> task3 >> task4
  File "/home/airflow/.local/lib/python3.7/site-packages/airflow/models/taskmixin.py", line 87, in __rshift__
    self.set_downstream(other)
  File "/home/airflow/.local/lib/python3.7/site-packages/airflow/models/taskmixin.py", line 236, in set_downstream
    self._set_relatives(task_or_task_list, upstream=False, edge_modifier=edge_modifier)
  File "/home/airflow/.local/lib/python3.7/site-packages/airflow/models/taskmixin.py", line 195, in _set_relatives
    raise AirflowException(f"Tried to set relationships between tasks in more than one DAG: {dags}")
airflow.exceptions.AirflowException: Tried to set relationships between tasks in more than one DAG: {<DAG: dag2>, <DAG: dag1>}
[2023-04-11T10:32:51.206+0000] {processor.py:755} WARNING - No viable dags retrieved from /opt/airflow/dags/dag_triggers_another_dag.py
[2023-04-11T10:32:51.271+0000] {processor.py:175} INFO - Processing /opt/airflow/dags/dag_triggers_another_dag.py took 0.213 seconds
[2023-04-11T10:33:22.115+0000] {processor.py:153} INFO - Started process (PID=2501) to work on /opt/airflow/dags/dag_triggers_another_dag.py
[2023-04-11T10:33:22.117+0000] {processor.py:743} INFO - Processing file /opt/airflow/dags/dag_triggers_another_dag.py for tasks to queue
[2023-04-11T10:33:22.119+0000] {logging_mixin.py:137} INFO - [2023-04-11T10:33:22.118+0000] {dagbag.py:532} INFO - Filling up the DagBag from /opt/airflow/dags/dag_triggers_another_dag.py
[2023-04-11T10:33:22.190+0000] {logging_mixin.py:137} INFO - [2023-04-11T10:33:22.173+0000] {dagbag.py:341} ERROR - Failed to import: /opt/airflow/dags/dag_triggers_another_dag.py
Traceback (most recent call last):
  File "/home/airflow/.local/lib/python3.7/site-packages/airflow/models/dagbag.py", line 337, in parse
    loader.exec_module(new_module)
  File "<frozen importlib._bootstrap_external>", line 728, in exec_module
  File "<frozen importlib._bootstrap>", line 219, in _call_with_frames_removed
  File "/opt/airflow/dags/dag_triggers_another_dag.py", line 70, in <module>
    trigger >> task3 >> task4
  File "/home/airflow/.local/lib/python3.7/site-packages/airflow/models/taskmixin.py", line 87, in __rshift__
    self.set_downstream(other)
  File "/home/airflow/.local/lib/python3.7/site-packages/airflow/models/taskmixin.py", line 236, in set_downstream
    self._set_relatives(task_or_task_list, upstream=False, edge_modifier=edge_modifier)
  File "/home/airflow/.local/lib/python3.7/site-packages/airflow/models/taskmixin.py", line 195, in _set_relatives
    raise AirflowException(f"Tried to set relationships between tasks in more than one DAG: {dags}")
airflow.exceptions.AirflowException: Tried to set relationships between tasks in more than one DAG: {<DAG: dag1>, <DAG: dag2>}
[2023-04-11T10:33:22.191+0000] {processor.py:755} WARNING - No viable dags retrieved from /opt/airflow/dags/dag_triggers_another_dag.py
[2023-04-11T10:33:22.233+0000] {processor.py:175} INFO - Processing /opt/airflow/dags/dag_triggers_another_dag.py took 0.122 seconds
[2023-04-11T10:33:52.448+0000] {processor.py:153} INFO - Started process (PID=2538) to work on /opt/airflow/dags/dag_triggers_another_dag.py
[2023-04-11T10:33:52.450+0000] {processor.py:743} INFO - Processing file /opt/airflow/dags/dag_triggers_another_dag.py for tasks to queue
[2023-04-11T10:33:52.452+0000] {logging_mixin.py:137} INFO - [2023-04-11T10:33:52.452+0000] {dagbag.py:532} INFO - Filling up the DagBag from /opt/airflow/dags/dag_triggers_another_dag.py
[2023-04-11T10:33:52.556+0000] {logging_mixin.py:137} INFO - [2023-04-11T10:33:52.529+0000] {dagbag.py:341} ERROR - Failed to import: /opt/airflow/dags/dag_triggers_another_dag.py
Traceback (most recent call last):
  File "/home/airflow/.local/lib/python3.7/site-packages/airflow/models/dagbag.py", line 337, in parse
    loader.exec_module(new_module)
  File "<frozen importlib._bootstrap_external>", line 728, in exec_module
  File "<frozen importlib._bootstrap>", line 219, in _call_with_frames_removed
  File "/opt/airflow/dags/dag_triggers_another_dag.py", line 70, in <module>
    trigger >> task3 >> task4
  File "/home/airflow/.local/lib/python3.7/site-packages/airflow/models/taskmixin.py", line 87, in __rshift__
    self.set_downstream(other)
  File "/home/airflow/.local/lib/python3.7/site-packages/airflow/models/taskmixin.py", line 236, in set_downstream
    self._set_relatives(task_or_task_list, upstream=False, edge_modifier=edge_modifier)
  File "/home/airflow/.local/lib/python3.7/site-packages/airflow/models/taskmixin.py", line 195, in _set_relatives
    raise AirflowException(f"Tried to set relationships between tasks in more than one DAG: {dags}")
airflow.exceptions.AirflowException: Tried to set relationships between tasks in more than one DAG: {<DAG: dag1>, <DAG: dag2>}
[2023-04-11T10:33:52.565+0000] {processor.py:755} WARNING - No viable dags retrieved from /opt/airflow/dags/dag_triggers_another_dag.py
[2023-04-11T10:33:52.623+0000] {processor.py:175} INFO - Processing /opt/airflow/dags/dag_triggers_another_dag.py took 0.189 seconds
[2023-04-11T10:34:22.901+0000] {processor.py:153} INFO - Started process (PID=2575) to work on /opt/airflow/dags/dag_triggers_another_dag.py
[2023-04-11T10:34:22.903+0000] {processor.py:743} INFO - Processing file /opt/airflow/dags/dag_triggers_another_dag.py for tasks to queue
[2023-04-11T10:34:22.905+0000] {logging_mixin.py:137} INFO - [2023-04-11T10:34:22.905+0000] {dagbag.py:532} INFO - Filling up the DagBag from /opt/airflow/dags/dag_triggers_another_dag.py
[2023-04-11T10:34:22.993+0000] {logging_mixin.py:137} INFO - [2023-04-11T10:34:22.964+0000] {dagbag.py:341} ERROR - Failed to import: /opt/airflow/dags/dag_triggers_another_dag.py
Traceback (most recent call last):
  File "/home/airflow/.local/lib/python3.7/site-packages/airflow/models/dagbag.py", line 337, in parse
    loader.exec_module(new_module)
  File "<frozen importlib._bootstrap_external>", line 728, in exec_module
  File "<frozen importlib._bootstrap>", line 219, in _call_with_frames_removed
  File "/opt/airflow/dags/dag_triggers_another_dag.py", line 70, in <module>
    trigger >> task3 >> task4
  File "/home/airflow/.local/lib/python3.7/site-packages/airflow/models/taskmixin.py", line 87, in __rshift__
    self.set_downstream(other)
  File "/home/airflow/.local/lib/python3.7/site-packages/airflow/models/taskmixin.py", line 236, in set_downstream
    self._set_relatives(task_or_task_list, upstream=False, edge_modifier=edge_modifier)
  File "/home/airflow/.local/lib/python3.7/site-packages/airflow/models/taskmixin.py", line 195, in _set_relatives
    raise AirflowException(f"Tried to set relationships between tasks in more than one DAG: {dags}")
airflow.exceptions.AirflowException: Tried to set relationships between tasks in more than one DAG: {<DAG: dag2>, <DAG: dag1>}
[2023-04-11T10:34:22.994+0000] {processor.py:755} WARNING - No viable dags retrieved from /opt/airflow/dags/dag_triggers_another_dag.py
[2023-04-11T10:34:23.045+0000] {processor.py:175} INFO - Processing /opt/airflow/dags/dag_triggers_another_dag.py took 0.149 seconds
[2023-04-11T10:34:53.696+0000] {processor.py:153} INFO - Started process (PID=2612) to work on /opt/airflow/dags/dag_triggers_another_dag.py
[2023-04-11T10:34:53.698+0000] {processor.py:743} INFO - Processing file /opt/airflow/dags/dag_triggers_another_dag.py for tasks to queue
[2023-04-11T10:34:53.700+0000] {logging_mixin.py:137} INFO - [2023-04-11T10:34:53.700+0000] {dagbag.py:532} INFO - Filling up the DagBag from /opt/airflow/dags/dag_triggers_another_dag.py
[2023-04-11T10:34:53.777+0000] {logging_mixin.py:137} INFO - [2023-04-11T10:34:53.767+0000] {dagbag.py:341} ERROR - Failed to import: /opt/airflow/dags/dag_triggers_another_dag.py
Traceback (most recent call last):
  File "/home/airflow/.local/lib/python3.7/site-packages/airflow/models/dagbag.py", line 337, in parse
    loader.exec_module(new_module)
  File "<frozen importlib._bootstrap_external>", line 728, in exec_module
  File "<frozen importlib._bootstrap>", line 219, in _call_with_frames_removed
  File "/opt/airflow/dags/dag_triggers_another_dag.py", line 70, in <module>
    trigger >> task3 >> task4
  File "/home/airflow/.local/lib/python3.7/site-packages/airflow/models/taskmixin.py", line 87, in __rshift__
    self.set_downstream(other)
  File "/home/airflow/.local/lib/python3.7/site-packages/airflow/models/taskmixin.py", line 236, in set_downstream
    self._set_relatives(task_or_task_list, upstream=False, edge_modifier=edge_modifier)
  File "/home/airflow/.local/lib/python3.7/site-packages/airflow/models/taskmixin.py", line 195, in _set_relatives
    raise AirflowException(f"Tried to set relationships between tasks in more than one DAG: {dags}")
airflow.exceptions.AirflowException: Tried to set relationships between tasks in more than one DAG: {<DAG: dag1>, <DAG: dag2>}
[2023-04-11T10:34:53.777+0000] {processor.py:755} WARNING - No viable dags retrieved from /opt/airflow/dags/dag_triggers_another_dag.py
[2023-04-11T10:34:53.833+0000] {processor.py:175} INFO - Processing /opt/airflow/dags/dag_triggers_another_dag.py took 0.148 seconds
[2023-04-11T10:35:23.991+0000] {processor.py:153} INFO - Started process (PID=2653) to work on /opt/airflow/dags/dag_triggers_another_dag.py
[2023-04-11T10:35:23.994+0000] {processor.py:743} INFO - Processing file /opt/airflow/dags/dag_triggers_another_dag.py for tasks to queue
[2023-04-11T10:35:23.996+0000] {logging_mixin.py:137} INFO - [2023-04-11T10:35:23.996+0000] {dagbag.py:532} INFO - Filling up the DagBag from /opt/airflow/dags/dag_triggers_another_dag.py
[2023-04-11T10:35:24.293+0000] {logging_mixin.py:137} INFO - [2023-04-11T10:35:24.158+0000] {dagbag.py:341} ERROR - Failed to import: /opt/airflow/dags/dag_triggers_another_dag.py
Traceback (most recent call last):
  File "/home/airflow/.local/lib/python3.7/site-packages/airflow/models/dagbag.py", line 337, in parse
    loader.exec_module(new_module)
  File "<frozen importlib._bootstrap_external>", line 728, in exec_module
  File "<frozen importlib._bootstrap>", line 219, in _call_with_frames_removed
  File "/opt/airflow/dags/dag_triggers_another_dag.py", line 70, in <module>
    trigger >> task3 >> task4
  File "/home/airflow/.local/lib/python3.7/site-packages/airflow/models/taskmixin.py", line 87, in __rshift__
    self.set_downstream(other)
  File "/home/airflow/.local/lib/python3.7/site-packages/airflow/models/taskmixin.py", line 236, in set_downstream
    self._set_relatives(task_or_task_list, upstream=False, edge_modifier=edge_modifier)
  File "/home/airflow/.local/lib/python3.7/site-packages/airflow/models/taskmixin.py", line 195, in _set_relatives
    raise AirflowException(f"Tried to set relationships between tasks in more than one DAG: {dags}")
airflow.exceptions.AirflowException: Tried to set relationships between tasks in more than one DAG: {<DAG: dag2>, <DAG: dag1>}
[2023-04-11T10:35:24.302+0000] {processor.py:755} WARNING - No viable dags retrieved from /opt/airflow/dags/dag_triggers_another_dag.py
[2023-04-11T10:35:24.431+0000] {processor.py:175} INFO - Processing /opt/airflow/dags/dag_triggers_another_dag.py took 0.459 seconds
[2023-04-11T10:35:54.910+0000] {processor.py:153} INFO - Started process (PID=2689) to work on /opt/airflow/dags/dag_triggers_another_dag.py
[2023-04-11T10:35:54.913+0000] {processor.py:743} INFO - Processing file /opt/airflow/dags/dag_triggers_another_dag.py for tasks to queue
[2023-04-11T10:35:54.924+0000] {logging_mixin.py:137} INFO - [2023-04-11T10:35:54.923+0000] {dagbag.py:532} INFO - Filling up the DagBag from /opt/airflow/dags/dag_triggers_another_dag.py
[2023-04-11T10:35:55.243+0000] {logging_mixin.py:137} INFO - [2023-04-11T10:35:55.212+0000] {dagbag.py:341} ERROR - Failed to import: /opt/airflow/dags/dag_triggers_another_dag.py
Traceback (most recent call last):
  File "/home/airflow/.local/lib/python3.7/site-packages/airflow/models/dagbag.py", line 337, in parse
    loader.exec_module(new_module)
  File "<frozen importlib._bootstrap_external>", line 728, in exec_module
  File "<frozen importlib._bootstrap>", line 219, in _call_with_frames_removed
  File "/opt/airflow/dags/dag_triggers_another_dag.py", line 70, in <module>
    trigger >> task3 >> task4
  File "/home/airflow/.local/lib/python3.7/site-packages/airflow/models/taskmixin.py", line 87, in __rshift__
    self.set_downstream(other)
  File "/home/airflow/.local/lib/python3.7/site-packages/airflow/models/taskmixin.py", line 236, in set_downstream
    self._set_relatives(task_or_task_list, upstream=False, edge_modifier=edge_modifier)
  File "/home/airflow/.local/lib/python3.7/site-packages/airflow/models/taskmixin.py", line 195, in _set_relatives
    raise AirflowException(f"Tried to set relationships between tasks in more than one DAG: {dags}")
airflow.exceptions.AirflowException: Tried to set relationships between tasks in more than one DAG: {<DAG: dag1>, <DAG: dag2>}
[2023-04-11T10:35:55.246+0000] {processor.py:755} WARNING - No viable dags retrieved from /opt/airflow/dags/dag_triggers_another_dag.py
[2023-04-11T10:35:55.363+0000] {processor.py:175} INFO - Processing /opt/airflow/dags/dag_triggers_another_dag.py took 0.470 seconds
[2023-04-11T10:36:26.077+0000] {processor.py:153} INFO - Started process (PID=2726) to work on /opt/airflow/dags/dag_triggers_another_dag.py
[2023-04-11T10:36:26.084+0000] {processor.py:743} INFO - Processing file /opt/airflow/dags/dag_triggers_another_dag.py for tasks to queue
[2023-04-11T10:36:26.089+0000] {logging_mixin.py:137} INFO - [2023-04-11T10:36:26.089+0000] {dagbag.py:532} INFO - Filling up the DagBag from /opt/airflow/dags/dag_triggers_another_dag.py
[2023-04-11T10:36:26.187+0000] {logging_mixin.py:137} INFO - [2023-04-11T10:36:26.178+0000] {dagbag.py:341} ERROR - Failed to import: /opt/airflow/dags/dag_triggers_another_dag.py
Traceback (most recent call last):
  File "/home/airflow/.local/lib/python3.7/site-packages/airflow/models/dagbag.py", line 337, in parse
    loader.exec_module(new_module)
  File "<frozen importlib._bootstrap_external>", line 728, in exec_module
  File "<frozen importlib._bootstrap>", line 219, in _call_with_frames_removed
  File "/opt/airflow/dags/dag_triggers_another_dag.py", line 70, in <module>
    trigger >> task3 >> task4
  File "/home/airflow/.local/lib/python3.7/site-packages/airflow/models/taskmixin.py", line 87, in __rshift__
    self.set_downstream(other)
  File "/home/airflow/.local/lib/python3.7/site-packages/airflow/models/taskmixin.py", line 236, in set_downstream
    self._set_relatives(task_or_task_list, upstream=False, edge_modifier=edge_modifier)
  File "/home/airflow/.local/lib/python3.7/site-packages/airflow/models/taskmixin.py", line 195, in _set_relatives
    raise AirflowException(f"Tried to set relationships between tasks in more than one DAG: {dags}")
airflow.exceptions.AirflowException: Tried to set relationships between tasks in more than one DAG: {<DAG: dag1>, <DAG: dag2>}
[2023-04-11T10:36:26.188+0000] {processor.py:755} WARNING - No viable dags retrieved from /opt/airflow/dags/dag_triggers_another_dag.py
[2023-04-11T10:36:26.241+0000] {processor.py:175} INFO - Processing /opt/airflow/dags/dag_triggers_another_dag.py took 0.170 seconds
[2023-04-11T10:36:56.579+0000] {processor.py:153} INFO - Started process (PID=2760) to work on /opt/airflow/dags/dag_triggers_another_dag.py
[2023-04-11T10:36:56.583+0000] {processor.py:743} INFO - Processing file /opt/airflow/dags/dag_triggers_another_dag.py for tasks to queue
[2023-04-11T10:36:56.597+0000] {logging_mixin.py:137} INFO - [2023-04-11T10:36:56.597+0000] {dagbag.py:532} INFO - Filling up the DagBag from /opt/airflow/dags/dag_triggers_another_dag.py
[2023-04-11T10:36:56.945+0000] {logging_mixin.py:137} INFO - [2023-04-11T10:36:56.872+0000] {dagbag.py:341} ERROR - Failed to import: /opt/airflow/dags/dag_triggers_another_dag.py
Traceback (most recent call last):
  File "/home/airflow/.local/lib/python3.7/site-packages/airflow/models/dagbag.py", line 337, in parse
    loader.exec_module(new_module)
  File "<frozen importlib._bootstrap_external>", line 728, in exec_module
  File "<frozen importlib._bootstrap>", line 219, in _call_with_frames_removed
  File "/opt/airflow/dags/dag_triggers_another_dag.py", line 70, in <module>
    trigger >> task3 >> task4
  File "/home/airflow/.local/lib/python3.7/site-packages/airflow/models/taskmixin.py", line 87, in __rshift__
    self.set_downstream(other)
  File "/home/airflow/.local/lib/python3.7/site-packages/airflow/models/taskmixin.py", line 236, in set_downstream
    self._set_relatives(task_or_task_list, upstream=False, edge_modifier=edge_modifier)
  File "/home/airflow/.local/lib/python3.7/site-packages/airflow/models/taskmixin.py", line 195, in _set_relatives
    raise AirflowException(f"Tried to set relationships between tasks in more than one DAG: {dags}")
airflow.exceptions.AirflowException: Tried to set relationships between tasks in more than one DAG: {<DAG: dag2>, <DAG: dag1>}
[2023-04-11T10:36:56.946+0000] {processor.py:755} WARNING - No viable dags retrieved from /opt/airflow/dags/dag_triggers_another_dag.py
[2023-04-11T10:36:57.038+0000] {processor.py:175} INFO - Processing /opt/airflow/dags/dag_triggers_another_dag.py took 0.477 seconds
[2023-04-11T10:37:29.660+0000] {processor.py:153} INFO - Started process (PID=2797) to work on /opt/airflow/dags/dag_triggers_another_dag.py
[2023-04-11T10:37:29.681+0000] {processor.py:743} INFO - Processing file /opt/airflow/dags/dag_triggers_another_dag.py for tasks to queue
[2023-04-11T10:37:29.684+0000] {logging_mixin.py:137} INFO - [2023-04-11T10:37:29.684+0000] {dagbag.py:532} INFO - Filling up the DagBag from /opt/airflow/dags/dag_triggers_another_dag.py
[2023-04-11T10:37:30.382+0000] {logging_mixin.py:137} INFO - [2023-04-11T10:37:30.237+0000] {dagbag.py:341} ERROR - Failed to import: /opt/airflow/dags/dag_triggers_another_dag.py
Traceback (most recent call last):
  File "/home/airflow/.local/lib/python3.7/site-packages/airflow/models/dagbag.py", line 337, in parse
    loader.exec_module(new_module)
  File "<frozen importlib._bootstrap_external>", line 728, in exec_module
  File "<frozen importlib._bootstrap>", line 219, in _call_with_frames_removed
  File "/opt/airflow/dags/dag_triggers_another_dag.py", line 70, in <module>
    trigger >> task3 >> task4
  File "/home/airflow/.local/lib/python3.7/site-packages/airflow/models/taskmixin.py", line 87, in __rshift__
    self.set_downstream(other)
  File "/home/airflow/.local/lib/python3.7/site-packages/airflow/models/taskmixin.py", line 236, in set_downstream
    self._set_relatives(task_or_task_list, upstream=False, edge_modifier=edge_modifier)
  File "/home/airflow/.local/lib/python3.7/site-packages/airflow/models/taskmixin.py", line 195, in _set_relatives
    raise AirflowException(f"Tried to set relationships between tasks in more than one DAG: {dags}")
airflow.exceptions.AirflowException: Tried to set relationships between tasks in more than one DAG: {<DAG: dag2>, <DAG: dag1>}
[2023-04-11T10:37:30.384+0000] {processor.py:755} WARNING - No viable dags retrieved from /opt/airflow/dags/dag_triggers_another_dag.py
[2023-04-11T10:37:30.548+0000] {processor.py:175} INFO - Processing /opt/airflow/dags/dag_triggers_another_dag.py took 0.896 seconds
[2023-04-11T10:38:03.023+0000] {processor.py:153} INFO - Started process (PID=2834) to work on /opt/airflow/dags/dag_triggers_another_dag.py
[2023-04-11T10:38:03.060+0000] {processor.py:743} INFO - Processing file /opt/airflow/dags/dag_triggers_another_dag.py for tasks to queue
[2023-04-11T10:38:03.077+0000] {logging_mixin.py:137} INFO - [2023-04-11T10:38:03.077+0000] {dagbag.py:532} INFO - Filling up the DagBag from /opt/airflow/dags/dag_triggers_another_dag.py
[2023-04-11T10:38:04.132+0000] {logging_mixin.py:137} INFO - [2023-04-11T10:38:04.067+0000] {dagbag.py:341} ERROR - Failed to import: /opt/airflow/dags/dag_triggers_another_dag.py
Traceback (most recent call last):
  File "/home/airflow/.local/lib/python3.7/site-packages/airflow/models/dagbag.py", line 337, in parse
    loader.exec_module(new_module)
  File "<frozen importlib._bootstrap_external>", line 728, in exec_module
  File "<frozen importlib._bootstrap>", line 219, in _call_with_frames_removed
  File "/opt/airflow/dags/dag_triggers_another_dag.py", line 70, in <module>
    trigger >> task3 >> task4
  File "/home/airflow/.local/lib/python3.7/site-packages/airflow/models/taskmixin.py", line 87, in __rshift__
    self.set_downstream(other)
  File "/home/airflow/.local/lib/python3.7/site-packages/airflow/models/taskmixin.py", line 236, in set_downstream
    self._set_relatives(task_or_task_list, upstream=False, edge_modifier=edge_modifier)
  File "/home/airflow/.local/lib/python3.7/site-packages/airflow/models/taskmixin.py", line 195, in _set_relatives
    raise AirflowException(f"Tried to set relationships between tasks in more than one DAG: {dags}")
airflow.exceptions.AirflowException: Tried to set relationships between tasks in more than one DAG: {<DAG: dag2>, <DAG: dag1>}
[2023-04-11T10:38:04.134+0000] {processor.py:755} WARNING - No viable dags retrieved from /opt/airflow/dags/dag_triggers_another_dag.py
[2023-04-11T10:38:04.251+0000] {processor.py:175} INFO - Processing /opt/airflow/dags/dag_triggers_another_dag.py took 1.250 seconds
[2023-04-11T10:38:34.660+0000] {processor.py:153} INFO - Started process (PID=2872) to work on /opt/airflow/dags/dag_triggers_another_dag.py
[2023-04-11T10:38:34.671+0000] {processor.py:743} INFO - Processing file /opt/airflow/dags/dag_triggers_another_dag.py for tasks to queue
[2023-04-11T10:38:34.674+0000] {logging_mixin.py:137} INFO - [2023-04-11T10:38:34.674+0000] {dagbag.py:532} INFO - Filling up the DagBag from /opt/airflow/dags/dag_triggers_another_dag.py
[2023-04-11T10:38:34.892+0000] {logging_mixin.py:137} INFO - [2023-04-11T10:38:34.823+0000] {dagbag.py:341} ERROR - Failed to import: /opt/airflow/dags/dag_triggers_another_dag.py
Traceback (most recent call last):
  File "/home/airflow/.local/lib/python3.7/site-packages/airflow/models/dagbag.py", line 337, in parse
    loader.exec_module(new_module)
  File "<frozen importlib._bootstrap_external>", line 728, in exec_module
  File "<frozen importlib._bootstrap>", line 219, in _call_with_frames_removed
  File "/opt/airflow/dags/dag_triggers_another_dag.py", line 70, in <module>
    trigger >> task3 >> task4
  File "/home/airflow/.local/lib/python3.7/site-packages/airflow/models/taskmixin.py", line 87, in __rshift__
    self.set_downstream(other)
  File "/home/airflow/.local/lib/python3.7/site-packages/airflow/models/taskmixin.py", line 236, in set_downstream
    self._set_relatives(task_or_task_list, upstream=False, edge_modifier=edge_modifier)
  File "/home/airflow/.local/lib/python3.7/site-packages/airflow/models/taskmixin.py", line 195, in _set_relatives
    raise AirflowException(f"Tried to set relationships between tasks in more than one DAG: {dags}")
airflow.exceptions.AirflowException: Tried to set relationships between tasks in more than one DAG: {<DAG: dag1>, <DAG: dag2>}
[2023-04-11T10:38:34.907+0000] {processor.py:755} WARNING - No viable dags retrieved from /opt/airflow/dags/dag_triggers_another_dag.py
[2023-04-11T10:38:35.055+0000] {processor.py:175} INFO - Processing /opt/airflow/dags/dag_triggers_another_dag.py took 0.402 seconds
[2023-04-11T10:39:05.536+0000] {processor.py:153} INFO - Started process (PID=2906) to work on /opt/airflow/dags/dag_triggers_another_dag.py
[2023-04-11T10:39:05.549+0000] {processor.py:743} INFO - Processing file /opt/airflow/dags/dag_triggers_another_dag.py for tasks to queue
[2023-04-11T10:39:05.551+0000] {logging_mixin.py:137} INFO - [2023-04-11T10:39:05.551+0000] {dagbag.py:532} INFO - Filling up the DagBag from /opt/airflow/dags/dag_triggers_another_dag.py
[2023-04-11T10:39:05.795+0000] {logging_mixin.py:137} INFO - [2023-04-11T10:39:05.725+0000] {dagbag.py:341} ERROR - Failed to import: /opt/airflow/dags/dag_triggers_another_dag.py
Traceback (most recent call last):
  File "/home/airflow/.local/lib/python3.7/site-packages/airflow/models/dagbag.py", line 337, in parse
    loader.exec_module(new_module)
  File "<frozen importlib._bootstrap_external>", line 728, in exec_module
  File "<frozen importlib._bootstrap>", line 219, in _call_with_frames_removed
  File "/opt/airflow/dags/dag_triggers_another_dag.py", line 70, in <module>
    trigger >> task3 >> task4
  File "/home/airflow/.local/lib/python3.7/site-packages/airflow/models/taskmixin.py", line 87, in __rshift__
    self.set_downstream(other)
  File "/home/airflow/.local/lib/python3.7/site-packages/airflow/models/taskmixin.py", line 236, in set_downstream
    self._set_relatives(task_or_task_list, upstream=False, edge_modifier=edge_modifier)
  File "/home/airflow/.local/lib/python3.7/site-packages/airflow/models/taskmixin.py", line 195, in _set_relatives
    raise AirflowException(f"Tried to set relationships between tasks in more than one DAG: {dags}")
airflow.exceptions.AirflowException: Tried to set relationships between tasks in more than one DAG: {<DAG: dag2>, <DAG: dag1>}
[2023-04-11T10:39:05.814+0000] {processor.py:755} WARNING - No viable dags retrieved from /opt/airflow/dags/dag_triggers_another_dag.py
[2023-04-11T10:39:05.880+0000] {processor.py:175} INFO - Processing /opt/airflow/dags/dag_triggers_another_dag.py took 0.350 seconds
